2021-11-22 17:04:33,456 |           flt.pandoc |    ERROR | Traceback (most recent call last):
  File "/usr/local/lib/python3.8/dist-packages/foliant/backends/pandoc.py", line 296, in _build_flat
    run(command, shell=True, check=True, stdout=PIPE, stderr=STDOUT)
  File "/usr/lib/python3.8/subprocess.py", line 512, in run
    raise CalledProcessError(retcode, process.args,
subprocess.CalledProcessError: Command 'pandoc --output "test-2021-11-22.pdf"     -f markdown __folianttmp__/__all__.md' returned non-zero exit status 43.

During handling of the above exception, another exception occurred:

Traceback (most recent call last):
  File "/usr/local/lib/python3.8/dist-packages/foliant/utils.py", line 158, in spinner
    yield
  File "/usr/local/lib/python3.8/dist-packages/foliant/backends/pandoc.py", line 382, in make
    result.append(self._build_flat(target))
  File "/usr/local/lib/python3.8/dist-packages/foliant/backends/pandoc.py", line 301, in _build_flat
    raise RuntimeError(f'Build failed: {exception.output.decode()}')
RuntimeError: Build failed: Error producing PDF.
! Package inputenc Error: Unicode character ÐŸ (U+041F)
(inputenc)                not set up for use with LaTeX.

See the inputenc package documentation for explanation.
Type  H <return>  for immediate help.
 ...                                              
                                                  
l.59 ...30-ux440ux430ux431ux43eux442ux44b-action}}

Try running pandoc with --pdf-engine=xelatex.


2021-11-22 17:04:33,463 |                  flt | CRITICAL | No result returned by backend
