2021-11-22 17:16:58,661 |           flt.mkdocs |    ERROR | Traceback (most recent call last):
  File "/usr/local/lib/python3.8/dist-packages/foliant/backends/mkdocs.py", line 167, in make
    config['pages'] = self._get_pages_with_headings(config['pages'])
  File "/usr/local/lib/python3.8/dist-packages/foliant/backends/mkdocs.py", line 145, in _get_pages_with_headings
    new_pages = _recursive_process_pages(pages, False)
  File "/usr/local/lib/python3.8/dist-packages/foliant/backends/mkdocs.py", line 131, in _recursive_process_pages
    new_pages_subset.append(_recursive_process_pages(item, False))
  File "/usr/local/lib/python3.8/dist-packages/foliant/backends/mkdocs.py", line 135, in _recursive_process_pages
    new_pages_subset = self._get_page_with_optional_heading(pages_subset)
  File "/usr/local/lib/python3.8/dist-packages/foliant/backends/mkdocs.py", line 92, in _get_page_with_optional_heading
    with open(page_file_full_path, encoding='utf8') as page_file:
FileNotFoundError: [Errno 2] No such file or directory: '__folianttmp__/docs.mkdocs.src/docs/test.md'

During handling of the above exception, another exception occurred:

Traceback (most recent call last):
  File "/usr/local/lib/python3.8/dist-packages/foliant/utils.py", line 158, in spinner
    yield
  File "/usr/local/lib/python3.8/dist-packages/foliant/backends/mkdocs.py", line 226, in make
    raise RuntimeError(f'Build failed: {exception}')
RuntimeError: Build failed: [Errno 2] No such file or directory: '__folianttmp__/docs.mkdocs.src/docs/test.md'

2021-11-22 17:16:58,820 |                  flt | CRITICAL | No result returned by backend
